Workbook

Sheet Executive Dashboard
A1: ALDI Procurement Performance Dashboard — FY 2025
A3: Prepared by: Mohammed Kaif Ahmed | MSc Strategy Management, Dublin City University
A5: Total Spend (€) | D5: Cost Savings Rate | G5: Avg Supplier Score | J5: Budget Variance
A6: ='Budget vs Actual'!S13 -> 178040000 | D6: ='Cost Savings Tracker'!B26 -> 0.077874564 | G6: =AVERAGE('Supplier Scorecard'!H4:H37) -> 3.8205882 | J6: ='Budget vs Actual'!U13 -> 0.011303607
A8: Category | B8: 2025 Spend (€)
A9: Fresh Produce | B9: =SUMIFS('Spend Analysis'!F$4:F$38,'Spend Analysis'!A$4:A$38,A9) -> 27609331
A10: Packaged Foods | B10: =SUMIFS('Spend Analysis'!F$4:F$38,'Spend Analysis'!A$4:A$38,A10) -> 16300433
A11: Beverages | B11: =SUMIFS('Spend Analysis'!F$4:F$38,'Spend Analysis'!A$4:A$38,A11) -> 6552356
A12: Packaging Materials | B12: =SUMIFS('Spend Analysis'!F$4:F$38,'Spend Analysis'!A$4:A$38,A12) -> 4665483
A13: Logistics & Transport | B13: =SUMIFS('Spend Analysis'!F$4:F$38,'Spend Analysis'!A$4:A$38,A13) -> 2958253
A14: Store Equipment | B14: =SUMIFS('Spend Analysis'!F$4:F$38,'Spend Analysis'!A$4:A$38,A14) -> 0
A15: IT Services | B15: =SUMIFS('Spend Analysis'!F$4:F$38,'Spend Analysis'!A$4:A$38,A15) -> 0
A16: Marketing & Advertising | B16: =SUMIFS('Spend Analysis'!F$4:F$38,'Spend Analysis'!A$4:A$38,A16) -> 0
A17: Facilities Management | B17: =SUMIFS('Spend Analysis'!F$4:F$38,'Spend Analysis'!A$4:A$38,A17) -> 0
A19: Top Suppliers | B19: Spend (€)
A20: Ülker Bisküvi | B20: =SUMIFS('Spend Analysis'!F$4:F$38,'Spend Analysis'!C$4:C$38,A20) -> 4336145
A21: Frutura Group | B21: =SUMIFS('Spend Analysis'!F$4:F$38,'Spend Analysis'!C$4:C$38,A21) -> 7255420
A22: Greenyard NV | B22: =SUMIFS('Spend Analysis'!F$4:F$38,'Spend Analysis'!C$4:C$38,A22) -> 7518278
A23: Bel Group | B23: =SUMIFS('Spend Analysis'!F$4:F$38,'Spend Analysis'!C$4:C$38,A23) -> 1569723
A24: Smurfit Kappa | B24: =SUMIFS('Spend Analysis'!F$4:F$38,'Spend Analysis'!C$4:C$38,A24) -> 384066
A25: Univeg Trade | B25: =SUMIFS('Spend Analysis'!F$4:F$38,'Spend Analysis'!C$4:C$38,A25) -> 5201461
A26: Refresco Group | B26: =SUMIFS('Spend Analysis'!F$4:F$38,'Spend Analysis'!C$4:C$38,A26) -> 1370317
A27: Barilla Group | B27: =SUMIFS('Spend Analysis'!F$4:F$38,'Spend Analysis'!C$4:C$38,A27) -> 3199951
A28: Rauch Fruchtsäfte | B28: =SUMIFS('Spend Analysis'!F$4:F$38,'Spend Analysis'!C$4:C$38,A28) -> 628423
A29: Müller Fresh Foods | B29: =SUMIFS('Spend Analysis'!F$4:F$38,'Spend Analysis'!C$4:C$38,A29) -> 918922
A31: Month | B31: Spend (€)
A32: Jan | B32: =SUMIFS('Data Input'!G:G,'Data Input'!B:B,">="&DATE(2025,1,1),'Data Input'!B:B,"<"&DATE(2025,2,1)) -> 4500000
A33: Feb | B33: =SUMIFS('Data Input'!G:G,'Data Input'!B:B,">="&DATE(2025,2,1),'Data Input'!B:B,"<"&DATE(2025,3,1)) -> 6000000
A34: Mar | B34: =SUMIFS('Data Input'!G:G,'Data Input'!B:B,">="&DATE(2025,3,1),'Data Input'!B:B,"<"&DATE(2025,4,1)) -> 2500000
A35: Apr | B35: =SUMIFS('Data Input'!G:G,'Data Input'!B:B,">="&DATE(2025,4,1),'Data Input'!B:B,"<"&DATE(2025,5,1)) -> 3000000
A36: May | B36: =SUMIFS('Data Input'!G:G,'Data Input'!B:B,">="&DATE(2025,5,1),'Data Input'!B:B,"<"&DATE(2025,6,1)) -> 3500000
A37: Jun | B37: =SUMIFS('Data Input'!G:G,'Data Input'!B:B,">="&DATE(2025,6,1),'Data Input'!B:B,"<"&DATE(2025,7,1)) -> 2500000
A38: Jul | B38: =SUMIFS('Data Input'!G:G,'Data Input'!B:B,">="&DATE(2025,7,1),'Data Input'!B:B,"<"&DATE(2025,8,1)) -> 2500000
A39: Aug | B39: =SUMIFS('Data Input'!G:G,'Data Input'!B:B,">="&DATE(2025,8,1),'Data Input'!B:B,"<"&DATE(2025,9,1)) -> 4000000
A40: Sep | B40: =SUMIFS('Data Input'!G:G,'Data Input'!B:B,">="&DATE(2025,9,1),'Data Input'!B:B,"<"&DATE(2025,10,1)) -> 2500000
A41: Oct | B41: =SUMIFS('Data Input'!G:G,'Data Input'!B:B,">="&DATE(2025,10,1),'Data Input'!B:B,"<"&DATE(2025,11,1)) -> 4500000
A42: Nov | B42: =SUMIFS('Data Input'!G:G,'Data Input'!B:B,">="&DATE(2025,11,1),'Data Input'!B:B,"<"&DATE(2025,12,1)) -> 3000000
A43: Dec | B43: =SUMIFS('Data Input'!G:G,'Data Input'!B:B,">="&DATE(2025,12,1),'Data Input'!B:B,"<"&DATE(2025,13,1)) -> 3500000
A45: Initiative Type | B45: Savings (€)
A46: Supplier Consolidation | B46: =SUMIFS('Cost Savings Tracker'!H$4:H$21,'Cost Savings Tracker'!D$4:D$21,A46) -> 2120000
...

Sheet Data Input
A1: Transaction ID | B1: Date | C1: Supplier | D1: Category | E1: Region | F1: Subcategory | G1: Amount (€) | H1: Payment Terms (Days) | I1: Purchase Order Number
A2: TXN-000001 | B2: 45710 | C2: Coca-Cola Europacific | D2: Beverages | E2: Austria | F2: Juices | G2: 500000 | H2: 60 | I2: PO-2025-00001
A3: TXN-000002 | B3: 45399 | C3: Carrier Refrigeration | D3: Store Equipment | E3: Austria | F3: Refrigeration | G3: 492091 | H3: 60 | I3: PO-2024-00002
A4: TXN-000003 | B4: 45803 | C4: Univeg Trade | D4: Fresh Produce | E4: Austria | F4: Meat & Poultry | G4: 500000 | H4: 90 | I4: PO-2025-00003
A5: TXN-000004 | B5: 45447 | C5: Müller Fresh Foods | D5: Fresh Produce | E5: Netherlands | F5: Dairy | G5: 500000 | H5: 15 | I5: PO-2024-00004
A6: TXN-000005 | B6: 45887 | C6: Barilla Group | D6: Packaged Foods | E6: Germany | F6: Cereals | G6: 500000 | H6: 15 | I6: PO-2025-00005
A7: TXN-000006 | B7: 45827 | C7: CBRE Group | D7: Facilities Management | E7: Germany | F7: HVAC Maintenance | G7: 500000 | H7: 30 | I7: PO-2025-00006
A8: TXN-000007 | B8: 45775 | C8: Smurfit Kappa | D8: Packaging Materials | E8: Austria | F8: Labels | G8: 500000 | H8: 15 | I8: PO-2025-00007
A9: TXN-000008 | B9: 45605 | C9: Barilla Group | D9: Packaged Foods | E9: Germany | F9: Snacks | G9: 500000 | H9: 60 | I9: PO-2024-00008
A10: TXN-000009 | B10: 45753 | C10: Infosys Europe | D10: IT Services | E10: Ireland | F10: Cybersecurity | G10: 500000 | H10: 45 | I10: PO-2025-00009
A11: TXN-000010 | B11: 45665 | C11: Ülker Bisküvi | D11: Packaged Foods | E11: UK | F11: Snacks | G11: 500000 | H11: 90 | I11: PO-2025-00010
A12: TXN-000011 | B12: 46002 | C12: Total Produce | D12: Fresh Produce | E12: Germany | F12: Fruits | G12: 500000 | H12: 30 | I12: PO-2025-00011
A13: TXN-000012 | B13: 45644 | C13: Eckes-Granini | D13: Beverages | E13: Germany | F13: Juices | G13: 500000 | H13: 60 | I13: PO-2024-00012
... A131: TXN-000130 | B131: 45402 | C131: CBRE Group | D131: Facilities Management | E131: UK | F131: HVAC Maintenance | G131: 500000 | H131: 90 | I131: PO-2024-00130

Sheet Spend Analysis
A1: ALDI Procurement Spend Analysis 2024-2025
A3: Category | B3: Subcategory | C3: Supplier | D3: Region | E3: 2024 Spend (€) | F3: 2025 Spend (€) | G3: YoY Change % | H3: Share of Total %
A4: Fresh Produce | B4: Dairy | C4: Frutura Group | D4: Germany | E4: 4477469 | F4: 4802344 | G4: =IFERROR((F4-E4)/E4,0) -> 0.072557733 | H4: =IFERROR(F4/SUM(F$4:F$38),0) -> 0.08267665
A5: Fresh Produce | B5: Vegetables | C5: Frutura Group | D5: UK | E5: 2222838 | F5: 2453076 | G5: =IFERROR((F5-E5)/E5,0) -> 0.1035784 | H5: =IFERROR(F5/SUM(F$4:F$38),0) -> 0.042231899
A6: Fresh Produce | B6: Fruits | C6: Greenyard NV | D6: Austria | E6: 2978245 | F6: 3200127 | G6: =IFERROR((F6-E6)/E6,0) -> 0.074500923 | H6: =IFERROR(F6/SUM(F$4:F$38),0) -> 0.055093051
A7: Fresh Produce | B7: Fruits | C7: Greenyard NV | D7: Ireland | E7: 1487026 | F7: 1495267 | G7: =IFERROR((F7-E7)/E7,0) -> 0.005541934 | H7: =IFERROR(F7/SUM(F$4:F$38),0) -> 0.02574236
A8: Fresh Produce | B8: Meat & Poultry | C8: Greenyard NV | D8: Germany | E8: 2902807 | F8: 2822884 | G8: =IFERROR((F8-E8)/E8,0) -> -0.027533005 | H8: =IFERROR(F8/SUM(F$4:F$38),0) -> 0.048598475
A9: Fresh Produce | B9: Dairy | C9: Total Produce | D9: Ireland | E9: 1490987 | F9: 1655758 | G9: =IFERROR((F9-E9)/E9,0) -> 0.11051136 | H9: =IFERROR(F9/SUM(F$4:F$38),0) -> 0.028505356
A10: Fresh Produce | B10: Dairy | C10: Total Produce | D10: UK | E10: 2413650 | F10: 2431949 | G10: =IFERROR((F10-E10)/E10,0) -> 0.0075814638 | H10: =IFERROR(F10/SUM(F$4:F$38),0) -> 0.041868179
A11: Fresh Produce | B11: Fruits | C11: Total Produce | D11: Austria | E11: 2729062 | F11: 2627543 | G11: =IFERROR((F11-E11)/E11,0) -> -0.037199228 | H11: =IFERROR(F11/SUM(F$4:F$38),0) -> 0.045235504
A12: Fresh Produce | B12: Dairy | C12: Müller Fresh Foods | D12: Netherlands | E12: 903493 | F12: 918922 | G12: =IFERROR((F12-E12)/E12,0) -> 0.017077055 | H12: =IFERROR(F12/SUM(F$4:F$38),0) -> 0.015820065
A13: Fresh Produce | B13: Meat & Poultry | C13: Univeg Trade | D13: UK | E13: 1804054 | F13: 1943565 | G13: =IFERROR((F13-E13)/E13,0) -> 0.077331942 | H13: =IFERROR(F13/SUM(F$4:F$38),0) -> 0.033460211
A14: Fresh Produce | B14: Dairy | C14: Univeg Trade | D14: Austria | E14: 2989414 | F14: 3257896 | G14: =IFERROR((F14-E14)/E14,0) -> 0.089810913 | H14: =IFERROR(F14/SUM(F$4:F$38),0) -> 0.056087596
A15: Packaged Foods | B15: Frozen Foods | C15: Nestlé Europe | D15: Austria | E15: 1464796 | F15: 1611744 | G15: =IFERROR((F15-E15)/E15,0) -> 0.10031977 | H15: =IFERROR(F15/SUM(F$4:F$38),0) -> 0.027747616
... A38: Logistics & Transport | B38: Inbound Freight | C38: DB Schenker | D38: Germany | E38: 1367396 | F38: 1510492 | G38: =IFERROR((F38-E38)/E38,0) -> 0.10464854 | H38: =IFERROR(F38/SUM(F$4:F$38),0) -> 0.026004472
A39: TOTAL | E39: =SUM(E4:E38) -> 55959559 | F39: =SUM(F4:F38) -> 58085856 | G39: =IFERROR((F39-E39)/E39,0) -> 0.037997029 | H39: =SUM(H4:H38) -> 1
A42: Spend by Category & Region (€)
A43: Category | B43: Austria | C43: Germany | D43: Ireland | E43: Netherlands | F43: UK | G43: Total
A44: Fresh Produce | B44: =SUMIFS(F$4:F$38,A$4:A$38,A44,D$4:D$38,B$43) -> 9085566 | C44: =SUMIFS(F$4:F$38,A$4:A$38,A44,D$4:D$38,C$43) -> 7625228 | D44: =SUMIFS(F$4:F$38,A$4:A$38,A44,D$4:D$38,D$43) -> 3151025 | E44: =SUMIFS(F$4:F$38,A$4:A$38,A44,D$4:D$38,E$43) -> 918922 | F44: =SUMIFS(F$4:F$38,A$4:A$38,A44,D$4:D$38,F$43) -> 6828590 | G44: =SUM(B44:F44) -> 27609331
A45: Packaged Foods | B45: =SUMIFS(F$4:F$38,A$4:A$38,A45,D$4:D$38,B$43) -> 4811695 | C45: =SUMIFS(F$4:F$38,A$4:A$38,A45,D$4:D$38,C$43) -> 4351772 | D45: =SUMIFS(F$4:F$38,A$4:A$38,A45,D$4:D$38,D$43) -> 599419 | E45: =SUMIFS(F$4:F$38,A$4:A$38,A45,D$4:D$38,E$43) -> 2605850 | F45: =SUMIFS(F$4:F$38,A$4:A$38,A45,D$4:D$38,F$43) -> 3931697 | G45: =SUM(B45:F45) -> 16300433
A46: Beverages | B46: =SUMIFS(F$4:F$38,A$4:A$38,A46,D$4:D$38,B$43) -> 1648946 | C46: =SUMIFS(F$4:F$38,A$4:A$38,A46,D$4:D$38,C$43) -> 2771333 | D46: =SUMIFS(F$4:F$38,A$4:A$38,A46,D$4:D$38,D$43) -> 566160 | E46: =SUMIFS(F$4:F$38,A$4:A$38,A46,D$4:D$38,E$43) -> 1008896 | F46: =SUMIFS(F$4:F$38,A$4:A$38,A46,D$4:D$38,F$43) -> 557021 | G46: =SUM(B46:F46) -> 6552356
A47: Packaging Materials | B47: =SUMIFS(F$4:F$38,A$4:A$38,A47,D$4:D$38,B$43) -> 1142117 | C47: =SUMIFS(F$4:F$38,A$4:A$38,A47,D$4:D$38,C$43) -> 1470024 | D47: =SUMIFS(F$4:F$38,A$4:A$38,A47,D$4:D$38,D$43) -> 0 | E47: =SUMIFS(F$4:F$38,A$4:A$38,A47,D$4:D$38,E$43) -> 518102 | F47: =SUMIFS(F$4:F$38,A$4:A$38,A47,D$4:D$38,F$43) -> 1535240 | G47: =SUM(B47:F47) -> 4665483
A48: Logistics & Transport | B48: =SUMIFS(F$4:F$38,A$4:A$38,A48,D$4:D$38,B$43) -> 0 | C48: =SUMIFS(F$4:F$38,A$4:A$38,A48,D$4:D$38,C$43) -> 1510492 | D48: =SUMIFS(F$4:F$38,A$4:A$38,A48,D$4:D$38,D$43) -> 514453 | E48: =SUMIFS(F$4:F$38,A$4:A$38,A48,D$4:D$38,E$43) -> 0 | F48: =SUMIFS(F$4:F$38,A$4:A$38,A48,D$4:D$38,F$43) -> 933308 | G48: =SUM(B48:F48) -> 2958253
A49: Store Equipment | B49: =SUMIFS(F$4:F$38,A$4:A$38,A49,D$4:D$38,B$43) -> 0 | C49: =SUMIFS(F$4:F$38,A$4:A$38,A49,D$4:D$38,C$43) -> 0 | D49: =SUMIFS(F$4:F$38,A$4:A$38,A49,D$4:D$38,D$43) -> 0 | E49: =SUMIFS(F$4:F$38,A$4:A$38,A49,D$4:D$38,E$43) -> 0 | F49: =SUMIFS(F$4:F$38,A$4:A$38,A49,D$4:D$38,F$43) -> 0 | G49: =SUM(B49:F49) -> 0
A50: IT Services | B50: =SUMIFS(F$4:F$38,A$4:A$38,A50,D$4:D$38,B$43) -> 0 | C50: =SUMIFS(F$4:F$38,A$4:A$38,A50,D$4:D$38,C$43) -> 0 | D50: =SUMIFS(F$4:F$38,A$4:A$38,A50,D$4:D$38,D$43) -> 0 | E50: =SUMIFS(F$4:F$38,A$4:A$38,A50,D$4:D$38,E$43) -> 0 | F50: =SUMIFS(F$4:F$38,A$4:A$38,A50,D$4:D$38,F$43) -> 0 | G50: =SUM(B50:F50) -> 0
A51: Marketing & Advertising | B51: =SUMIFS(F$4:F$38,A$4:A$38,A51,D$4:D$38,B$43) -> 0 | C51: =SUMIFS(F$4:F$38,A$4:A$38,A51,D$4:D$38,C$43) -> 0 | D51: =SUMIFS(F$4:F$38,A$4:A$38,A51,D$4:D$38,D$43) -> 0 | E51: =SUMIFS(F$4:F$38,A$4:A$38,A51,D$4:D$38,E$43) -> 0 | F51: =SUMIFS(F$4:F$38,A$4:A$38,A51,D$4:D$38,F$43) -> 0 | G51: =SUM(B51:F51) -> 0
A52: Facilities Management | B52: =SUMIFS(F$4:F$38,A$4:A$38,A52,D$4:D$38,B$43) -> 0 | C52: =SUMIFS(F$4:F$38,A$4:A$38,A52,D$4:D$38,C$43) -> 0 | D52: =SUMIFS(F$4:F$38,A$4:A$38,A52,D$4:D$38,D$43) -> 0 | E52: =SUMIFS(F$4:F$38,A$4:A$38,A52,D$4:D$38,E$43) -> 0 | F52: =SUMIFS(F$4:F$38,A$4:A$38,A52,D$4:D$38,F$43) -> 0 | G52: =SUM(B52:F52) -> 0

Sheet Supplier Scorecard
A1: Supplier Performance Scorecard
A2: Weights: Quality 30% | Delivery 25% | Cost 25% | Innovation 20%
A3: Supplier Name | B3: Category | C3: Quality Score (1-5) | D3: Delivery Performance (%) | E3: Cost Competitiveness (1-5) | F3: Payment Terms (Days) | G3: Innovation Score (1-5) | H3: Overall Rating | I3: Status
A4: Frutura Group | B4: Fresh Produce | C4: 2.7 | D4: 0.769 | E4: 4 | F4: 15 | G4: 2.4 | H4: =(C4*0.3)+(D4*5*0.25)+(E4*0.25)+(G4*0.2) -> 3.25125 | I4: =IF(H4>4,"Excellent",IF(H4>3.5,"Good",IF(H4>3,"Acceptable","Review Required"))) -> Acceptable
A5: Greenyard NV | B5: Fresh Produce | C5: 4.1 | D5: 0.89 | E5: 4.3 | F5: 60 | G5: 5 | H5: =(C5*0.3)+(D5*5*0.25)+(E5*0.25)+(G5*0.2) -> 4.4175 | I5: =IF(H5>4,"Excellent",IF(H5>3.5,"Good",IF(H5>3,"Acceptable","Review Required"))) -> Excellent
A6: Total Produce | B6: Fresh Produce | C6: 3.8 | D6: 0.859 | E6: 4 | F6: 15 | G6: 4.4 | H6: =(C6*0.3)+(D6*5*0.25)+(E6*0.25)+(G6*0.2) -> 4.09375 | I6: =IF(H6>4,"Excellent",IF(H6>3.5,"Good",IF(H6>3,"Acceptable","Review Required"))) -> Excellent
A7: Müller Fresh Foods | B7: Fresh Produce | C7: 2.2 | D7: 0.772 | E7: 4.7 | F7: 90 | G7: 2.5 | H7: =(C7*0.3)+(D7*5*0.25)+(E7*0.25)+(G7*0.2) -> 3.3 | I7: =IF(H7>4,"Excellent",IF(H7>3.5,"Good",IF(H7>3,"Acceptable","Review Required"))) -> Acceptable
A8: Univeg Trade | B8: Fresh Produce | C8: 3 | D8: 0.858 | E8: 3.1 | F8: 45 | G8: 4.5 | H8: =(C8*0.3)+(D8*5*0.25)+(E8*0.25)+(G8*0.2) -> 3.6475 | I8: =IF(H8>4,"Excellent",IF(H8>3.5,"Good",IF(H8>3,"Acceptable","Review Required"))) -> Good
A9: Nestlé Europe | B9: Packaged Foods | C9: 3.5 | D9: 0.925 | E9: 3.3 | F9: 45 | G9: 4 | H9: =(C9*0.3)+(D9*5*0.25)+(E9*0.25)+(G9*0.2) -> 3.83125 | I9: =IF(H9>4,"Excellent",IF(H9>3.5,"Good",IF(H9>3,"Acceptable","Review Required"))) -> Good
A10: Dr. Oetker GmbH | B10: Packaged Foods | C10: 3.4 | D10: 0.787 | E10: 4.8 | F10: 15 | G10: 2.3 | H10: =(C10*0.3)+(D10*5*0.25)+(E10*0.25)+(G10*0.2) -> 3.66375 | I10: =IF(H10>4,"Excellent",IF(H10>3.5,"Good",IF(H10>3,"Acceptable","Review Required"))) -> Good
A11: Barilla Group | B11: Packaged Foods | C11: 2.7 | D11: 0.854 | E11: 4.4 | F11: 45 | G11: 4.4 | H11: =(C11*0.3)+(D11*5*0.25)+(E11*0.25)+(G11*0.2) -> 3.8575 | I11: =IF(H11>4,"Excellent",IF(H11>3.5,"Good",IF(H11>3,"Acceptable","Review Required"))) -> Good
A12: Bel Group | B12: Packaged Foods | C12: 3.9 | D12: 0.891 | E12: 3.9 | F12: 45 | G12: 4 | H12: =(C12*0.3)+(D12*5*0.25)+(E12*0.25)+(G12*0.2) -> 4.05875 | I12: =IF(H12>4,"Excellent",IF(H12>3.5,"Good",IF(H12>3,"Acceptable","Review Required"))) -> Excellent
A13: Ülker Bisküvi | B13: Packaged Foods | C13: 3.5 | D13: 0.96 | E13: 4.9 | F13: 60 | G13: 4.6 | H13: =(C13*0.3)+(D13*5*0.25)+(E13*0.25)+(G13*0.2) -> 4.395 | I13: =IF(H13>4,"Excellent",IF(H13>3.5,"Good",IF(H13>3,"Acceptable","Review Required"))) -> Excellent
A14: Refresco Group | B14: Beverages | C14: 4.3 | D14: 0.982 | E14: 4 | F14: 45 | G14: 2.3 | H14: =(C14*0.3)+(D14*5*0.25)+(E14*0.25)+(G14*0.2) -> 3.9775 | I14: =IF(H14>4,"Excellent",IF(H14>3.5,"Good",IF(H14>3,"Acceptable","Review Required"))) -> Good
A15: Rauch Fruchtsäfte | B15: Beverages | C15: 3.8 | D15: 0.787 | E15: 3.7 | F15: 15 | G15: 3.1 | H15: =(C15*0.3)+(D15*5*0.25)+(E15*0.25)+(G15*0.2) -> 3.66875 | I15: =IF(H15>4,"Excellent",IF(H15>3.5,"Good",IF(H15>3,"Acceptable","Review Required"))) -> Good
... A37: CBRE Group | B37: Facilities Management | C37: 4.9 | D37: 0.905 | E37: 2.9 | F37: 15 | G37: 2.4 | H37: =(C37*0.3)+(D37*5*0.25)+(E37*0.25)+(G37*0.2) -> 3.80625 | I37: =IF(H37>4,"Excellent",IF(H37>3.5,"Good",IF(H37>3,"Acceptable","Review Required"))) -> Good

Sheet Cost Savings Tracker
A1: Procurement Cost Savings Tracker 2025
A3: Initiative ID | B3: Initiative Name | C3: Category | D3: Initiative Type | E3: Baseline Cost (€) | F3: Target Cost (€) | G3: Actual Cost (€) | H3: Savings Achieved (€) | I3: Savings % | J3: Status | K3: Implementation Date | L3: Owner
A4: SAV-001 | B4: Fresh Produce Supplier Consolidation | C4: Fresh Produce | D4: Supplier Consolidation | E4: 12500000 | F4: 11250000 | G4: 11100000 | H4: =E4-G4 -> 1400000 | I4: =IFERROR(H4/E4,0) -> 0.112 | J4: Completed | K4: 45672 | L4: M. Gruber
A5: SAV-002 | B5: Packaging Contract Renegotiation | C5: Packaging Materials | D5: Contract Renegotiation | E5: 5800000 | F5: 5400000 | G5: 5350000 | H5: =E5-G5 -> 450000 | I5: =IFERROR(H5/E5,0) -> 0.077586207 | J5: Completed | K5: 45689 | L5: S. Fischer
A6: SAV-003 | B6: Logistics Route Optimization | C6: Logistics & Transport | D6: Process Automation | E6: 8200000 | F6: 7800000 | G6: 7750000 | H6: =E6-G6 -> 450000 | I6: =IFERROR(H6/E6,0) -> 0.054878049 | J6: Completed | K6: 45677 | L6: L. Weber
A7: SAV-004 | B7: IT Services Vendor Consolidation | C7: IT Services | D7: Supplier Consolidation | E7: 2100000 | F7: 1900000 | G7: 1880000 | H7: =E7-G7 -> 220000 | I7: =IFERROR(H7/E7,0) -> 0.1047619 | J7: Completed | K7: 45717 | L7: K. Müller
A8: SAV-005 | B8: Beverages Strategic Sourcing | C8: Beverages | D8: Strategic Sourcing | E8: 7500000 | F8: 7000000 | G8: 6950000 | H8: =E8-G8 -> 550000 | I8: =IFERROR(H8/E8,0) -> 0.073333333 | J8: Completed | K8: 45703 | L8: T. Schmidt
A9: SAV-006 | B9: Store Equipment Spec Optimization | C9: Store Equipment | D9: Specification Optimization | E9: 3800000 | F9: 3500000 | G9: 3520000 | H9: =E9-G9 -> 280000 | I9: =IFERROR(H9/E9,0) -> 0.073684211 | J9: Completed | K9: 45748 | L9: A. Wagner
A10: SAV-007 | B10: Packaged Foods Volume Bundling | C10: Packaged Foods | D10: Strategic Sourcing | E10: 15200000 | F10: 14200000 | G10: 14050000 | H10: =E10-G10 -> 1150000 | I10: =IFERROR(H10/E10,0) -> 0.075657895 | J10: Completed | K10: 45731 | L10: M. Gruber
A11: SAV-008 | B11: Facilities Management Automation | C11: Facilities Management | D11: Process Automation | E11: 2200000 | F11: 2000000 | G11: 1980000 | H11: =E11-G11 -> 220000 | I11: =IFERROR(H11/E11,0) -> 0.1 | J11: Completed | K11: 45778 | L11: S. Fischer
A12: SAV-009 | B12: Marketing Digital Transition | C12: Marketing & Advertising | D12: Demand Management | E12: 2500000 | F12: 2250000 | G12: 2200000 | H12: =E12-G12 -> 300000 | I12: =IFERROR(H12/E12,0) -> 0.12 | J12: Completed | K12: 45762 | L12: L. Weber
A13: SAV-010 | B13: Dairy Supply Chain Optimization | C13: Fresh Produce | D13: Strategic Sourcing | E13: 9800000 | F13: 9200000 | G13: 9150000 | H13: =E13-G13 -> 650000 | I13: =IFERROR(H13/E13,0) -> 0.066326531 | J13: Completed | K13: 45792 | L13: K. Müller
A14: SAV-011 | B14: Packaging Material Substitution | C14: Packaging Materials | D14: Specification Optimization | E14: 4200000 | F14: 3900000 | G14: 3880000 | H14: =E14-G14 -> 320000 | I14: =IFERROR(H14/E14,0) -> 0.076190476 | J14: Completed | K14: 45809 | L14: T. Schmidt
A15: SAV-012 | B15: Beverage Contract Renewal | C15: Beverages | D15: Contract Renegotiation | E15: 6000000 | F15: 5600000 | G15: 5700000 | H15: =E15-G15 -> 300000 | I15: =IFERROR(H15/E15,0) -> 0.05 | J15: In Progress | K15: 45839 | L15: A. Wagner
... A19: SAV-016 | B19: Cloud Migration Cost Reduction | C19: IT Services | D19: Process Automation | E19: 1800000 | F19: 1500000 | G19: 1600000 | H19: =E19-G19 -> 200000 | I19: =IFERROR(H19/E19,0) -> 0.11111111 | J19: In Progress | K19: 45962 | L19: K. Müller
A20: SAV-017 | B20: Fresh Produce Regional Sourcing | C20: Fresh Produce | D20: Strategic Sourcing | E20: 11000000 | F20: 10200000 | G20: — | H20: =E20-F20 -> 800000 | I20: =IFERROR(H20/E20,0) -> 0.072727273 | J20: Planned | K20: 46023 | L20: T. Schmidt
A21: SAV-018 | B21: Packaging Automation Phase 2 | C21: Packaging Materials | D21: Process Automation | E21: 3500000 | F21: 3100000 | G21: — | H21: =E21-F21 -> 400000 | I21: =IFERROR(H21/E21,0) -> 0.11428571 | J21: Planned | K21: 46054 | L21: A. Wagner
A23: SUMMARY
A24: Total Baseline Cost (€) | B24: =SUM(E4:E21) -> 114800000
A25: Total Savings Achieved (€) | B25: =SUM(H4:H21) -> 8940000
A26: Overall Savings Rate | B26: =IFERROR(B25/B24,0) -> 0.077874564
A28: Initiative Type | B28: Total Savings (€)
A29: Supplier Consolidation | B29: =SUMIFS(H$4:H$21,D$4:D$21,A29) -> 2120000
A30: Contract Renegotiation | B30: =SUMIFS(H$4:H$21,D$4:D$21,A30) -> 1000000
A31: Process Automation | B31: =SUMIFS(H$4:H$21,D$4:D$21,A31) -> 1270000
A32: Strategic Sourcing | B32: =SUMIFS(H$4:H$21,D$4:D$21,A32) -> 3150000
A33: Demand Management | B33: =SUMIFS(H$4:H$21,D$4:D$21,A33) -> 800000
A34: Specification Optimization | B34: =SUMIFS(H$4:H$21,D$4:D$21,A34) -> 600000

Sheet Business Case Calculator
A1: Business Case Calculator — Procurement Initiative
A3: Section 1: Investment Details
A5: Initiative Name | B5: Logistics Automation Platform
A6: Category | B6: Logistics & Transport
A7: Investment Required (€) | B7: 2500000
A8: Implementation Timeline (Months) | B8: 18
A9: Discount Rate | B9: 0.08
A12: Section 2: Annual Benefits Projection
A14: Benefit Category | B14: Year 1 | C14: Year 2 | D14: Year 3 | E14: Year 4 | F14: Year 5
A15: Cost Reduction | B15: 450000 | C15: 520000 | D15: 580000 | E15: 620000 | F15: 650000
A16: Efficiency Gains | B16: 180000 | C16: 220000 | D16: 260000 | E16: 290000 | F16: 310000
A17: Risk Mitigation Value | B17: 80000 | C17: 95000 | D17: 110000 | E17: 120000 | F17: 130000
A18: Total Annual Benefit | B18: =SUM(B15:B17) -> 710000 | C18: =SUM(C15:C17) -> 835000 | D18: =SUM(D15:D17) -> 950000 | E18: =SUM(E15:E17) -> 1030000 | F18: =SUM(F15:F17) -> 1090000
A20: Section 3: Financial Metrics
A22: Year | B22: Year 0 | C22: Year 1 | D22: Year 2 | E22: Year 3 | F22: Year 4 | G22: Year 5
A23: Cash Flow (€) | B23: =-B7 -> -2500000 | C23: =B18 -> 710000 | D23: =C18 -> 835000 | E23: =D18 -> 950000 | F23: =E18 -> 1030000 | G23: =F18 -> 1090000
A24: Cumulative Cash Flow (€) | B24: =B23 -> -2500000 | C24: =B24+C23 -> -1790000 | D24: =C24+D23 -> -955000 | E24: =D24+E23 -> -5000 | F24: =E24+F23 -> 1025000 | G24: =F24+G23 -> 2115000
A26: NPV (€) | B26: =NPV(B9,C23:G23)+B23 -> 1126342.4
A27: IRR | B27: =IRR(B23:G23) -> 0.22593148
A28: ROI | B28: =IFERROR((SUM(C23:G23)+B23)/(-B23),0) -> 0.846
A29: Payback Period (Years) | B29: =IFERROR(MATCH(TRUE(),INDEX(B24:G24>0,0),0)-1,">5") -> 4
A31: Section 4: Sensitivity Analysis
B33: Benefit 80% | C33: Benefit 100% | D33: Benefit 120%
A34: Discount Rate 5% | B34: =NPV(0.05,C18*0.8,D18*0.8,E18*0.8,F18*0.8,G18*0.8)-B7 -> 254731.62 | C34: =NPV(0.05,C18*1,D18*1,E18*1,F18*1,G18*1)-B7 -> 943414.52 | D34: =NPV(0.05,C18*1.2,D18*1.2,E18*1.2,F18*1.2,G18*1.2)-B7 -> 1632097.4
A35: Discount Rate 7% | B35: =NPV(0.07,C18*0.8,D18*0.8,E18*0.8,F18*0.8,G18*0.8)-B7 -> 125986.57 | C35: =NPV(0.07,C18*1,D18*1,E18*1,F18*1,G18*1)-B7 -> 782483.22 | D35: =NPV(0.07,C18*1.2,D18*1.2,E18*1.2,F18*1.2,G18*1.2)-B7 -> 1438979.9
A36: Discount Rate 10% | B36: =NPV(0.1,C18*0.8,D18*0.8,E18*0.8,F18*0.8,G18*0.8)-B7 -> -49956.97 | C36: =NPV(0.1,C18*1,D18*1,E18*1,F18*1,G18*1)-B7 -> 562553.79 | D36: =NPV(0.1,C18*1.2,D18*1.2,E18*1.2,F18*1.2,G18*1.2)-B7 -> 1175064.5
A38: Section 5: Scenario Comparison
A40: Metric | B40: Best Case | C40: Base Case | D40: Worst Case
A41: NPV (€) | B41: =D34 -> 1632097.4 | C41: =B26 -> 1126342.4 | D41: =B36 -> -49956.97
A42: IRR | B42: =B27*1.15 -> 0.2598212 | C42: =B27 -> 0.22593148 | D42: =B27*0.75 -> 0.16944861
A43: ROI | B43: =IFERROR((SUM(C23:G23)*1.2+B23)/(-B23),0) -> 1.2152 | C43: =B28 -> 0.846 | D43: =IFERROR((SUM(C23:G23)*0.8+B23)/(-B23),0) -> 0.4768
A44: Payback (Years) | B44: < 3 years | C44: =B29 -> 4 | D44: > 4 years

Sheet Budget vs Actual
A1: Budget vs Actual Analysis — FY 2025
A3: Category | B3: Q1 Budget (€) | C3: Q1 Actual (€) | D3: Q1 Variance (€) | E3: Q1 Var % | F3: Q2 Budget (€) | G3: Q2 Actual (€) | H3: Q2 Variance (€) | I3: Q2 Var % | J3: Q3 Budget (€) | K3: Q3 Actual (€) | L3: Q3 Variance (€) | M3: Q3 Var % | N3: Q4 Budget (€) | O3: Q4 Actual (€) | P3: Q4 Variance (€) | Q3: Q4 Var % | R3: Annual Budget (€) | S3: Annual Actual (€) | T3: Annual Variance (€) | U3: Annual Var % | V3: Commentary
A4: Fresh Produce | B4: 14000000 | C4: 14350000 | D4: =C4-B4 -> 350000 | E4: =IFERROR(D4/B4,0) -> 0.025 | F4: 13500000 | G4: 13200000 | H4: =G4-F4 -> -300000 | I4: =IFERROR(H4/F4,0) -> -0.022222222 | J4: 14500000 | K4: 14800000 | L4: =K4-J4 -> 300000 | M4: =IFERROR(L4/J4,0) -> 0.020689655 | N4: 15500000 | O4: 16100000 | P4: =O4-N4 -> 600000 | Q4: =IFERROR(P4/N4,0) -> 0.038709677 | R4: =B4+F4+J4+N4 -> 57500000 | S4: =C4+G4+K4+O4 -> 58450000 | T4: =S4-R4 -> 950000 | U4: =IFERROR(T4/R4,0) -> 0.016521739 | V4: Q4 above budget due to seasonal price increases
A5: Packaged Foods | B5: 11500000 | C5: 11400000 | D5: =C5-B5 -> -100000 | E5: =IFERROR(D5/B5,0) -> -0.0086956522 | F5: 11000000 | G5: 11200000 | H5: =G5-F5 -> 200000 | I5: =IFERROR(H5/F5,0) -> 0.018181818 | J5: 12000000 | K5: 11800000 | L5: =K5-J5 -> -200000 | M5: =IFERROR(L5/J5,0) -> -0.016666667 | N5: 13000000 | O5: 13500000 | P5: =O5-N5 -> 500000 | Q5: =IFERROR(P5/N5,0) -> 0.038461538 | R5: =B5+F5+J5+N5 -> 47500000 | S5: =C5+G5+K5+O5 -> 47900000 | T5: =S5-R5 -> 400000 | U5: =IFERROR(T5/R5,0) -> 0.0084210526 | V5: Q4 higher than planned; holiday inventory build-up
A6: Beverages | B6: 4200000 | C6: 4100000 | D6: =C6-B6 -> -100000 | E6: =IFERROR(D6/B6,0) -> -0.023809524 | F6: 4500000 | G6: 4650000 | H6: =G6-F6 -> 150000 | I6: =IFERROR(H6/F6,0) -> 0.033333333 | J6: 4800000 | K6: 4750000 | L6: =K6-J6 -> -50000 | M6: =IFERROR(L6/J6,0) -> -0.010416667 | N6: 4000000 | O6: 4200000 | P6: =O6-N6 -> 200000 | Q6: =IFERROR(P6/N6,0) -> 0.05 | R6: =B6+F6+J6+N6 -> 17500000 | S6: =C6+G6+K6+O6 -> 17700000 | T6: =S6-R6 -> 200000 | U6: =IFERROR(T6/R6,0) -> 0.011428571 | V6: Slight overspend in Q2; summer demand exceeded forecast
A7: Packaging Materials | B7: 3500000 | C7: 3450000 | D7: =C7-B7 -> -50000 | E7: =IFERROR(D7/B7,0) -> -0.014285714 | F7: 3400000 | G7: 3500000 | H7: =G7-F7 -> 100000 | I7: =IFERROR(H7/F7,0) -> 0.029411765 | J7: 3600000 | K7: 3550000 | L7: =K7-J7 -> -50000 | M7: =IFERROR(L7/J7,0) -> -0.013888889 | N7: 3800000 | O7: 3900000 | P7: =O7-N7 -> 100000 | Q7: =IFERROR(P7/N7,0) -> 0.026315789 | R7: =B7+F7+J7+N7 -> 14300000 | S7: =C7+G7+K7+O7 -> 14400000 | T7: =S7-R7 -> 100000 | U7: =IFERROR(T7/R7,0) -> 0.006993007 | V7: On track; minor Q2 variance from material cost rise
A8: Logistics & Transport | B8: 3800000 | C8: 3900000 | D8: =C8-B8 -> 100000 | E8: =IFERROR(D8/B8,0) -> 0.026315789 | F8: 3700000 | G8: 3650000 | H8: =G8-F8 -> -50000 | I8: =IFERROR(H8/F8,0) -> -0.013513514 | J8: 4000000 | K8: 4100000 | L8: =K8-J8 -> 100000 | M8: =IFERROR(L8/J8,0) -> 0.025 | N8: 4200000 | O8: 4350000 | P8: =O8-N8 -> 150000 | Q8: =IFERROR(P8/N8,0) -> 0.035714286 | R8: =B8+F8+J8+N8 -> 15700000 | S8: =C8+G8+K8+O8 -> 16000000 | T8: =S8-R8 -> 300000 | U8: =IFERROR(T8/R8,0) -> 0.01910828 | V8: Fuel surcharges drove Q3-Q4 overruns
A9: Store Equipment | B9: 2200000 | C9: 2100000 | D9: =C9-B9 -> -100000 | E9: =IFERROR(D9/B9,0) -> -0.045454545 | F9: 2000000 | G9: 2050000 | H9: =G9-F9 -> 50000 | I9: =IFERROR(H9/F9,0) -> 0.025 | J9: 2100000 | K9: 2000000 | L9: =K9-J9 -> -100000 | M9: =IFERROR(L9/J9,0) -> -0.047619048 | N9: 2500000 | O9: 2600000 | P9: =O9-N9 -> 100000 | Q9: =IFERROR(P9/N9,0) -> 0.04 | R9: =B9+F9+J9+N9 -> 8800000 | S9: =C9+G9+K9+O9 -> 8750000 | T9: =S9-R9 -> -50000 | U9: =IFERROR(T9/R9,0) -> -0.0056818182 | V9: Under budget overall; delayed Q3 installations
A10: IT Services | B10: 1200000 | C10: 1250000 | D10: =C10-B10 -> 50000 | E10: =IFERROR(D10/B10,0) -> 0.041666667 | F10: 1300000 | G10: 1280000 | H10: =G10-F10 -> -20000 | I10: =IFERROR(H10/F10,0) -> -0.015384615 | J10: 1100000 | K10: 1150000 | L10: =K10-J10 -> 50000 | M10: =IFERROR(L10/J10,0) -> 0.045454545 | N10: 1400000 | O10: 1380000 | P10: =O10-N10 -> -20000 | Q10: =IFERROR(P10/N10,0) -> -0.014285714 | R10: =B10+F10+J10+N10 -> 5000000 | S10: =C10+G10+K10+O10 -> 5060000 | T10: =S10-R10 -> 60000 | U10: =IFERROR(T10/R10,0) -> 0.012 | V10: Marginally over in Q1; unplanned cybersecurity upgrade
A11: Marketing & Advertising | B11: 1300000 | C11: 1250000 | D11: =C11-B11 -> -50000 | E11: =IFERROR(D11/B11,0) -> -0.038461538 | F11: 1400000 | G11: 1450000 | H11: =G11-F11 -> 50000 | I11: =IFERROR(H11/F11,0) -> 0.035714286 | J11: 1200000 | K11: 1180000 | L11: =K11-J11 -> -20000 | M11: =IFERROR(L11/J11,0) -> -0.016666667 | N11: 1500000 | O11: 1550000 | P11: =O11-N11 -> 50000 | Q11: =IFERROR(P11/N11,0) -> 0.033333333 | R11: =B11+F11+J11+N11 -> 5400000 | S11: =C11+G11+K11+O11 -> 5430000 | T11: =S11-R11 -> 30000 | U11: =IFERROR(T11/R11,0) -> 0.0055555556 | V11: Within tolerance; digital shift savings offset Q2 campaigns
A12: Facilities Management | B12: 1100000 | C12: 1080000 | D12: =C12-B12 -> -20000 | E12: =IFERROR(D12/B12,0) -> -0.018181818 | F12: 1000000 | G12: 1020000 | H12: =G12-F12 -> 20000 | I12: =IFERROR(H12/F12,0) -> 0.02 | J12: 1050000 | K12: 1000000 | L12: =K12-J12 -> -50000 | M12: =IFERROR(L12/J12,0) -> -0.047619048 | N12: 1200000 | O12: 1250000 | P12: =O12-N12 -> 50000 | Q12: =IFERROR(P12/N12,0) -> 0.041666667 | R12: =B12+F12+J12+N12 -> 4350000 | S12: =C12+G12+K12+O12 -> 4350000 | T12: =S12-R12 -> 0 | U12: =IFERROR(T12/R12,0) -> 0 | V12: Well managed; minor Q4 seasonal maintenance spike
A13: TOTAL | B13: =SUM(B4:B12) -> 42800000 | C13: =SUM(C4:C12) -> 42880000 | D13: =SUM(D4:D12) -> 80000 | E13: =IFERROR(D13/B13,0) -> 0.0018691589 | F13: =SUM(F4:F12) -> 41800000 | G13: =SUM(G4:G12) -> 42000000 | H13: =SUM(H4:H12) -> 200000 | I13: =IFERROR(H13/F13,0) -> 0.004784689 | J13: =SUM(J4:J12) -> 44350000 | K13: =SUM(K4:K12) -> 44330000 | L13: =SUM(L4:L12) -> -20000 | M13: =IFERROR(L13/J13,0) -> -0.00045095829 | N13: =SUM(N4:N12) -> 47100000 | O13: =SUM(O4:O12) -> 48830000 | P13: =SUM(P4:P12) -> 1730000 | Q13: =IFERROR(P13/N13,0) -> 0.036730361 | R13: =SUM(R4:R12) -> 176050000 | S13: =SUM(S4:S12) -> 178040000 | T13: =SUM(T4:T12) -> 1990000 | U13: =IFERROR(T13/R13,0) -> 0.011303607
A15: Quarter | B15: Budget (€) | C15: Actual (€)
A16: Q1 | B16: =SUM(B4:B12) -> 42800000 | C16: =SUM(C4:C12) -> 42880000
A17: Q2 | B17: =SUM(F4:F12) -> 41800000 | C17: =SUM(G4:G12) -> 42000000
A18: Q3 | B18: =SUM(J4:J12) -> 44350000 | C18: =SUM(K4:K12) -> 44330000
A19: Q4 | B19: =SUM(N4:N12) -> 47100000 | C19: =SUM(O4:O12) -> 48830000

Sheet Documentation
A1: Workbook Documentation & User Guide
A3: OVERVIEW
A4: This workbook provides a comprehensive procurement performance analytics platform
A5: designed for ALDI's Procurement & Performance Insights team. It demonstrates
A6: advanced Excel capabilities, procurement domain knowledge, and financial controlling skills.
A8: PREPARED BY | B8: Mohammed Kaif Ahmed
A9: PROGRAMME | B9: Strategy Management — Dublin City University
A10: DATE | B10: February 2025
A12: TAB DESCRIPTIONS
A13: Executive Dashboard | B13: High-level KPI summary with interactive charts. All data pulls dynamically from other tabs.
A14: Spend Analysis | B14: Detailed category and regional spend breakdown with YoY comparisons and pivot summaries.
A15: Supplier Scorecard | B15: Weighted performance evaluation of 25+ suppliers across Quality, Delivery, Cost, and Innovation.
A16: Cost Savings Tracker | B16: 18 procurement savings initiatives tracked from baseline to achievement with ROI metrics.
A17: Business Case Calculator | B17: Full NPV/IRR/ROI model with sensitivity analysis and scenario comparison for investment decisions.
A18: Budget vs Actual | B18: Quarterly budget variance analysis across all procurement categories with commentary.
A19: Data Input | B19: Raw transaction data (130+ rows) with data validation; feeds all analytical tabs.
A21: KEY FORMULAS USED
A22: SUMIFS | B22: Conditional aggregation across categories, regions, and time periods
A23: IFERROR | B23: Error handling to prevent division and reference errors
A24: NPV / IRR | B24: Net Present Value and Internal Rate of Return for business case evaluation
A25: INDEX / MATCH | B25: Flexible lookups for cross-tab data retrieval
A26: Weighted Average | B26: (Quality×30%) + (Delivery×25%) + (Cost×25%) + (Innovation×20%)
A27: IF / AND / OR | B27: Status classification and conditional logic throughout
A29: HOW TO USE
A30: 1. Start with the Executive Dashboard for a high-level overview of procurement performance.
A31: 2. Drill into Spend Analysis to understand category and regional spending patterns.
A32: 3. Review Supplier Scorecard to identify top performers and suppliers needing review.
A33: 4. Use Cost Savings Tracker to monitor initiative progress against targets.
A34: 5. Leverage Business Case Calculator for new procurement investment decisions.
A35: 6. Check Budget vs Actual for financial controlling and variance management.
A36: 7. Update Data Input tab to refresh all analytics automatically.
